<?xml version="1.0" encoding="UTF-8"?>
<testsuites>
	<testsuite errors="0" failures="1" name="MyTest-20181205231112" skipped="0" tests="2" time="2.070" timestamp="2018-12-05T23:11:14">
		<testcase classname="MyTest" name="test_dicts_extracted_into_kwargs_2" time="1.603" timestamp="2018-12-05T23:11:14"/>
		<testcase classname="MyTest" name="test_dicts_extracted_into_kwargs_1" time="0.467" timestamp="2018-12-05T23:11:13">
			<failure message="3 != 4" type="AssertionError">
<![CDATA[Traceback (most recent call last):
  File "C:\Python36\lib\site-packages\ddt.py", line 145, in wrapper
    return func(self, *args, **kwargs)
  File "D:/class_dev/test_dev_sample/test_platform/interface_app/extend/task_run.py", line 23, in test_dicts_extracted_into_kwargs
    self.assertEqual(2+1, 4)
AssertionError: 3 != 4
]]>			</failure>
		</testcase>
		<system-out>
<![CDATA[]]>		</system-out>
		<system-err>
<![CDATA[]]>		</system-err>
	</testsuite>
</testsuites>
